2019-10-02 00:50:06,488 ERROR: Exception on /index [GET] [in c:\code\microblog\venv\lib\site-packages\flask\app.py:1891]
Traceback (most recent call last):
  File "c:\code\microblog\venv\lib\site-packages\flask\app.py", line 2446, in wsgi_app
    response = self.full_dispatch_request()
  File "c:\code\microblog\venv\lib\site-packages\flask\app.py", line 1951, in full_dispatch_request
    rv = self.handle_user_exception(e)
  File "c:\code\microblog\venv\lib\site-packages\flask\app.py", line 1820, in handle_user_exception
    reraise(exc_type, exc_value, tb)
  File "c:\code\microblog\venv\lib\site-packages\flask\_compat.py", line 39, in reraise
    raise value
  File "c:\code\microblog\venv\lib\site-packages\flask\app.py", line 1949, in full_dispatch_request
    rv = self.dispatch_request()
  File "c:\code\microblog\venv\lib\site-packages\flask\app.py", line 1935, in dispatch_request
    return self.view_functions[rule.endpoint](**req.view_args)
  File "c:\code\microblog\venv\lib\site-packages\flask_login\utils.py", line 261, in decorated_view
    return func(*args, **kwargs)
  File "C:\Code\microblog\app\routes.py", line 29, in index
    next_url=next_url, prev_url=prev_url)
  File "c:\code\microblog\venv\lib\site-packages\flask\templating.py", line 138, in render_template
    ctx.app.jinja_env.get_or_select_template(template_name_or_list),
  File "c:\code\microblog\venv\lib\site-packages\jinja2\environment.py", line 869, in get_or_select_template
    return self.get_template(template_name_or_list, parent, globals)
  File "c:\code\microblog\venv\lib\site-packages\jinja2\environment.py", line 830, in get_template
    return self._load_template(name, self.make_globals(globals))
  File "c:\code\microblog\venv\lib\site-packages\jinja2\environment.py", line 804, in _load_template
    template = self.loader.load(self, name, globals)
  File "c:\code\microblog\venv\lib\site-packages\jinja2\loaders.py", line 125, in load
    code = environment.compile(source, name, filename)
  File "c:\code\microblog\venv\lib\site-packages\jinja2\environment.py", line 591, in compile
    self.handle_exception(exc_info, source_hint=source_hint)
  File "c:\code\microblog\venv\lib\site-packages\jinja2\environment.py", line 780, in handle_exception
    reraise(exc_type, exc_value, tb)
  File "c:\code\microblog\venv\lib\site-packages\jinja2\_compat.py", line 37, in reraise
    raise value.with_traceback(tb)
  File "C:\Code\microblog\app\templates\index.html", line 35, in template
    {% block app_content %}
  File "c:\code\microblog\venv\lib\site-packages\jinja2\environment.py", line 543, in _generate
    optimized=self.optimized)
  File "c:\code\microblog\venv\lib\site-packages\jinja2\compiler.py", line 82, in generate
    generator.visit(node)
  File "c:\code\microblog\venv\lib\site-packages\jinja2\visitor.py", line 38, in visit
    return f(node, *args, **kwargs)
  File "c:\code\microblog\venv\lib\site-packages\jinja2\compiler.py", line 718, in visit_Template
    self.fail('block %r defined twice' % block.name, block.lineno)
  File "c:\code\microblog\venv\lib\site-packages\jinja2\compiler.py", line 315, in fail
    raise TemplateAssertionError(msg, lineno, self.name, self.filename)
jinja2.exceptions.TemplateAssertionError: block 'app_content' defined twice
2019-10-02 00:51:34,420 INFO: Microblog startup [in C:\Code\microblog\app\__init__.py:46]
2019-10-02 00:52:41,700 INFO: Microblog startup [in C:\Code\microblog\app\__init__.py:46]
2019-10-02 01:03:23,581 INFO: Microblog startup [in C:\Code\microblog\app\__init__.py:48]
2019-10-02 01:03:49,327 INFO: Microblog startup [in C:\Code\microblog\app\__init__.py:48]
